<robot name="onshape">
<link name="torso">
<!-- Shapes for torso_top -->
<visual>
<origin xyz="0 0 0" rpy="0 -0 0" />
<geometry>
<mesh filename="meshes/torso_visual.stl"/>
</geometry>
<material name="torso_material">
<color rgba="0.0901961 0.0862745 0.0784314 1.0"/>
</material>
</visual>
<collision>
<origin xyz="0 0 0" rpy="0 -0 0" />
<geometry>
<mesh filename="meshes/torso_collision.stl"/>
</geometry>
<material name="torso_material">
<color rgba="0.0901961 0.0862745 0.0784314 1.0"/>
</material>
</collision>
<inertial>
<origin xyz="-0.00089052 -0.000101034 0.0941488" rpy="0 0 0"/>
<mass value="2.1698" />
<inertia ixx="0.018424" ixy="0.000144299"  ixz="-0.00111467" iyy="0.0159818" iyz="2.7567e-06" izz="0.00731365" />
</inertial>
</link>

<link name="left_hip_yaw">
<visual>
<origin xyz="0 0 0" rpy="0 -0 0" />
<geometry>
<mesh filename="meshes/left_hip_yaw_visual.stl"/>
</geometry>
<material name="left_hip_yaw_material">
<color rgba="0.0901961 0.0862745 0.0784314 1.0"/>
</material>
</visual>
<collision>
<origin xyz="0 0 0" rpy="0 -0 0" />
<geometry>
<mesh filename="meshes/left_hip_yaw_collision.stl"/>
</geometry>
<material name="left_hip_yaw_material">
<color rgba="0.5 0.5 0.5 1.0"/>
</material>
</collision>
<inertial>
<origin xyz="-0.0021828 -0.00894798 -0.0247563" rpy="0 0 0"/>
<mass value="0.0932944" />
<inertia ixx="8.23164e-05" ixy="-1.59276e-07"  ixz="7.33413e-07" iyy="0.000162773" iyz="-2.36193e-06" izz="0.00018631" />
</inertial>
</link>

<link name="left_hip_roll">
<visual>
<origin xyz="0 0 0" rpy="0 -0 0" />
<geometry>
<mesh filename="meshes/left_hip_roll_visual.stl"/>
</geometry>
<material name="left_hip_roll_material">
<color rgba="0.0901961 0.0862745 0.0784314 1.0"/>
</material>
</visual>
<collision>
<origin xyz="0 0 0" rpy="0 -0 0" />
<geometry>
<mesh filename="meshes/left_hip_roll_collision.stl"/>
</geometry>
<material name="left_hip_roll_material">
<color rgba="0.5 0.5 0.5 1.0"/>
</material>
</collision>
<inertial>
<origin xyz="0.015733 -0.000656594 0.0472427" rpy="0 0 0"/>
<mass value="0.395953" />
<inertia ixx="0.000314298" ixy="1.5275e-09"  ixz="9.66719e-18" iyy="0.000375808" iyz="5.62038e-06" izz="0.000127785" />
</inertial>
</link>

<link name="left_upper_leg">
<visual>
<origin xyz="0 0 0" rpy="0 -0 0" />
<geometry>
<mesh filename="meshes/left_upper_leg_visual.stl"/>
</geometry>
<material name="left_upper_leg_material">
<color rgba="0.0901961 0.0862745 0.0784314 1.0"/>
</material>
</visual>
<collision>
<origin xyz="0 0 0" rpy="0 -0 0" />
<geometry>
<mesh filename="meshes/left_upper_leg_collision.stl"/>
</geometry>
<material name="left_upper_leg_material">
<color rgba="0.5 0.5 0.5 1.0"/>
</material>
</collision>
<inertial>
<origin xyz="0.147465 -0.00207665 -0.00198983" rpy="0 0 0"/>
<mass value="1.24036" />
<inertia ixx="0.00189152" ixy="0.000525048"  ixz="-0.000298774" iyy="0.00604475" iyz="1.6858e-05" izz="0.00465372" />
</inertial>
</link>

<link name="lower_leg_left">
<visual>
<origin xyz="0 0 0" rpy="0 -0 0" />
<geometry>
<mesh filename="meshes/lower_leg_left_visual.stl"/>
</geometry>
<material name="lower_leg_left_material">
<color rgba="0.0901961 0.0862745 0.0784314 1.0"/>
</material>
</visual>
<collision>
<origin xyz="0 0 0" rpy="0 -0 0" />
<geometry>
<mesh filename="meshes/lower_leg_left_collision.stl"/>
</geometry>
<material name="lower_leg_left_material">
<color rgba="0.5 0.5 0.5 1.0"/>
</material>
</collision>
<inertial>
<origin xyz="0.100171 0.00428532 0.00169225" rpy="0 0 0"/>
<mass value="0.225756" />
<inertia ixx="0.000735047" ixy="0.000115989"  ixz="-0.000100527" iyy="0.00101559" iyz="6.19038e-05" izz="0.000444841" />
</inertial>
</link>

<link name="left_ankle">
<visual>
<origin xyz="0 0 0" rpy="0 -0 0" />
<geometry>
<mesh filename="meshes/left_ankle_visual.stl"/>
</geometry>
<material name="left_ankle_material">
<color rgba="0.0901961 0.0862745 0.0784314 1.0"/>
</material>
</visual>
<collision>
<origin xyz="0 0 0" rpy="0 -0 0" />
<geometry>
<mesh filename="meshes/left_ankle_collision.stl"/>
</geometry>
<material name="left_ankle_material">
<color rgba="0.5 0.5 0.5 1.0"/>
</material>
</collision>
<inertial>
<origin xyz="-0.015733 0.0219762 -0.000469844" rpy="0 0 0"/>
<mass value="0.329993" />
<inertia ixx="0.000265762" ixy="1.27304e-09"  ixz="2.22685e-18" iyy="0.000157847" iyz="3.6829e-06" izz="0.000265677" />
</inertial>
</link>

<link name="left_foot">
<visual>
<origin xyz="0 0 0" rpy="0 -0 0" />
<geometry>
<mesh filename="meshes/left_foot_visual.stl"/>
</geometry>
<material name="left_foot_material">
<color rgba="0.0901961 0.0862745 0.0784314 1.0"/>
</material>
</visual>
<collision>
<origin xyz="0 0 0" rpy="0 -0 0" />
<geometry>
<mesh filename="meshes/left_foot_collision.stl"/>
</geometry>
<material name="left_foot_material">
<color rgba="0.5 0.5 0.5 1.0"/>
</material>
</collision>
<inertial>
<origin xyz="0.02481 0.00798543 0.0333477" rpy="0 0 0"/>
<mass value="0.245582" />
<inertia ixx="0.00134722" ixy="-9.7626e-06"  ixz="7.02326e-09" iyy="0.00108395" iyz="-1.34064e-05" izz="0.000332151" />
</inertial>
</link>

<joint name="left_ankle_roll" type="revolute">
<origin xyz="-1.66533e-15 -6.94565e-06 -0.000982442" rpy="1.5708 -8.69144e-15 7.83425e-14" />
<parent link="left_ankle" />
<child link="left_foot" />
<axis xyz="0 0 1"/>
<limit effort="1" velocity="20" />
<joint_properties friction="0.0"/>
</joint>

<joint name="left_ankle_pitch" type="revolute">
<origin xyz="0.199419 -0.00566882 -0.0002" rpy="-2.21654e-15 1.5961e-15 2.03982e-19" />
<parent link="lower_leg_left" />
<child link="left_ankle" />
<axis xyz="0 0 1"/>
<limit effort="1" velocity="20" />
<joint_properties friction="0.0"/>
</joint>

<joint name="left_knee_pitch" type="revolute">
<origin xyz="0.199541 -2.33261e-05 -0.00095424" rpy="-2.65601e-14 -5.52844e-14 -3.59878e-05" />
<parent link="left_upper_leg" />
<child link="lower_leg_left" />
<axis xyz="0 0 1"/>
<limit effort="1" velocity="20" />
<joint_properties friction="0.0"/>
</joint>

<joint name="left_hip_pitch" type="revolute">
<origin xyz="-2.30371e-15 2.9564e-05 0.06895" rpy="-1.5708 1.38608e-12 1.27676e-15" />
<parent link="left_hip_roll" />
<child link="left_upper_leg" />
<axis xyz="0 0 1"/>
<limit effort="1" velocity="20" />
<joint_properties friction="0.0"/>
</joint>

<joint name="left_hip_roll" type="revolute">
<origin xyz="-0.04625 6.93889e-18 -0.0545" rpy="2.61845e-30 1.5708 0" />
<parent link="left_hip_yaw" />
<child link="left_hip_roll" />
<axis xyz="0 0 1"/>
<limit effort="1" velocity="20" />
<joint_properties friction="0.0"/>
</joint>

<joint name="left_hip_yaw" type="revolute">
<origin xyz="7.63278e-17 0.055 0.000499999" rpy="-3.33067e-16 1.61226e-15 2.60184e-14" />
<parent link="torso" />
<child link="left_hip_yaw" />
<axis xyz="0 0 1"/>
<limit effort="1" velocity="20" />
<joint_properties friction="0.0"/>
</joint>

<link name="right_hip_yaw">
<visual>
<origin xyz="0 0 0" rpy="0 -0 0" />
<geometry>
<mesh filename="meshes/right_hip_yaw_visual.stl"/>
</geometry>
<material name="right_hip_yaw_material">
<color rgba="0.0901961 0.0862745 0.0784314 1.0"/>
</material>
</visual>
<collision>
<origin xyz="0 0 0" rpy="0 -0 0" />
<geometry>
<mesh filename="meshes/right_hip_yaw_collision.stl"/>
</geometry>
<material name="right_hip_yaw_material">
<color rgba="0.5 0.5 0.5 1.0"/>
</material>
</collision>
<inertial>
<origin xyz="-0.00218277 0.0089479 -0.0247564" rpy="0 0 0"/>
<mass value="0.0932942" />
<inertia ixx="8.23152e-05" ixy="1.58741e-07"  ixz="7.33703e-07" iyy="0.000162773" iyz="2.36238e-06" izz="0.000186309" />
</inertial>
</link>

<link name="right_hip_roll">
<visual>
<origin xyz="0 0 0" rpy="0 -0 0" />
<geometry>
<mesh filename="meshes/right_hip_roll_visual.stl"/>
</geometry>
<material name="right_hip_roll_material">
<color rgba="0.0901961 0.0862745 0.0784314 1.0"/>
</material>
</visual>
<collision>
<origin xyz="0 0 0" rpy="0 -0 0" />
<geometry>
<mesh filename="meshes/right_hip_roll_collision.stl"/>
</geometry>
<material name="right_hip_roll_material">
<color rgba="0.5 0.5 0.5 1.0"/>
</material>
</collision>
<inertial>
<origin xyz="0.015733 -0.000656594 0.0472427" rpy="0 0 0"/>
<mass value="0.395953" />
<inertia ixx="0.000314298" ixy="1.5275e-09"  ixz="9.60705e-18" iyy="0.000375808" iyz="5.62038e-06" izz="0.000127785" />
</inertial>
</link>

<link name="right_upper_leg">
<visual>
<origin xyz="0 0 0" rpy="0 -0 0" />
<geometry>
<mesh filename="meshes/right_upper_leg_visual.stl"/>
</geometry>
<material name="right_upper_leg_material">
<color rgba="0.0901961 0.0862745 0.0784314 1.0"/>
</material>
</visual>
<collision>
<origin xyz="0 0 0" rpy="0 -0 0" />
<geometry>
<mesh filename="meshes/right_upper_leg_collision.stl"/>
</geometry>
<material name="right_upper_leg_material">
<color rgba="0.5 0.5 0.5 1.0"/>
</material>
</collision>
<inertial>
<origin xyz="0.147465 -0.00207665 -0.00253559" rpy="0 0 0"/>
<mass value="1.24036" />
<inertia ixx="0.00189152" ixy="0.000525048"  ixz="-0.000298774" iyy="0.00604475" iyz="1.6858e-05" izz="0.00465372" />
</inertial>
</link>

<link name="lower_leg_right">
<visual>
<origin xyz="0 0 0" rpy="0 -0 0" />
<geometry>
<mesh filename="meshes/lower_leg_right_visual.stl"/>
</geometry>
<material name="lower_leg_right_material">
<color rgba="0.0901961 0.0862745 0.0784314 1.0"/>
</material>
</visual>
<collision>
<origin xyz="0 0 0" rpy="0 -0 0" />
<geometry>
<mesh filename="meshes/lower_leg_right_collision.stl"/>
</geometry>
<material name="lower_leg_right_material">
<color rgba="0.5 0.5 0.5 1.0"/>
</material>
</collision>
<inertial>
<origin xyz="0.100171 0.0042893 -0.00174034" rpy="0 0 0"/>
<mass value="0.225702" />
<inertia ixx="0.000734773" ixy="0.000134273"  ixz="-6.14938e-05" iyy="0.000987501" iyz="0.000121567" izz="0.000472759" />
</inertial>
</link>

<link name="left_ankle_2">
<visual>
<origin xyz="0 0 0" rpy="0 -0 0" />
<geometry>
<mesh filename="meshes/left_ankle_2_visual.stl"/>
</geometry>
<material name="left_ankle_2_material">
<color rgba="0.0901961 0.0862745 0.0784314 1.0"/>
</material>
</visual>
<collision>
<origin xyz="0 0 0" rpy="0 -0 0" />
<geometry>
<mesh filename="meshes/left_ankle_2_collision.stl"/>
</geometry>
<material name="left_ankle_2_material">
<color rgba="0.5 0.5 0.5 1.0"/>
</material>
</collision>
<inertial>
<origin xyz="-0.015733 0.0219762 -0.000469844" rpy="0 0 0"/>
<mass value="0.329993" />
<inertia ixx="0.000265762" ixy="1.27304e-09"  ixz="1.10326e-18" iyy="0.000157847" iyz="3.6829e-06" izz="0.000265677" />
</inertial>
</link>

<link name="right_foot">
<visual>
<origin xyz="0 0 0" rpy="0 -0 0" />
<geometry>
<mesh filename="meshes/right_foot_visual.stl"/>
</geometry>
<material name="right_foot_material">
<color rgba="0.0901961 0.0862745 0.0784314 1.0"/>
</material>
</visual>
<collision>
<origin xyz="0 0 0" rpy="0 -0 0" />
<geometry>
<mesh filename="meshes/right_foot_collision.stl"/>
</geometry>
<material name="right_foot_material">
<color rgba="0.5 0.5 0.5 1.0"/>
</material>
</collision>
<inertial>
<origin xyz="0.0248229 -0.00798676 0.0332739" rpy="0 0 0"/>
<mass value="0.245568" />
<inertia ixx="0.00134712" ixy="9.73588e-06"  ixz="2.23513e-08" iyy="0.00108376" iyz="1.3404e-05" izz="0.000331998" />
</inertial>
</link>

<joint name="right_ankle_roll" type="revolute">
<origin xyz="-2.22045e-15 -0.000116046 -0.000982442" rpy="1.5708 -1.1811e-13 2.53365e-14" />
<parent link="left_ankle_2" />
<child link="right_foot" />
<axis xyz="0 0 1"/>
<limit effort="1" velocity="20" />
<joint_properties friction="0.0"/>
</joint>

<joint name="right_ankle_pitch" type="revolute">
<origin xyz="0.199419 -0.00566882 0.0015" rpy="-1.28717e-16 6.42564e-16 -1.12766e-16" />
<parent link="lower_leg_right" />
<child link="left_ankle_2" />
<axis xyz="0 0 1"/>
<limit effort="1" velocity="20" />
<joint_properties friction="0.0"/>
</joint>

<joint name="right_knee_pitch" type="revolute">
<origin xyz="0.199541 -2.33261e-05 -0.0015" rpy="-2.84504e-14 -5.46771e-14 6.40122e-05" />
<parent link="right_upper_leg" />
<child link="lower_leg_right" />
<axis xyz="0 0 1"/>
<limit effort="1" velocity="20" />
<joint_properties friction="0.0"/>
</joint>

<joint name="right_hip_pitch" type="revolute">
<origin xyz="-2.20657e-15 2.9564e-05 0.06895" rpy="-1.5708 -4.44818e-05 9.43671e-16" />
<parent link="right_hip_roll" />
<child link="right_upper_leg" />
<axis xyz="0 0 1"/>
<limit effort="1" velocity="20" />
<joint_properties friction="0.0"/>
</joint>

<joint name="right_hip_roll" type="revolute">
<origin xyz="-0.04625 6.93889e-18 -0.0545" rpy="-2.62033e-30 1.5708 0" />
<parent link="right_hip_yaw" />
<child link="right_hip_roll" />
<axis xyz="0 0 1"/>
<limit effort="1" velocity="20" />
<joint_properties friction="0.0"/>
</joint>

<joint name="right_hip_yaw" type="revolute">
<origin xyz="-1.16226e-16 -0.055 0.000499999" rpy="-3.33067e-16 1.68034e-15 3.82823e-14" />
<parent link="torso" />
<child link="right_hip_yaw" />
<axis xyz="0 0 1"/>
<limit effort="1" velocity="20" />
<joint_properties friction="0.0"/>
</joint>

<link name="left_shoulder">
<visual>
<origin xyz="0 0 0" rpy="0 -0 0" />
<geometry>
<mesh filename="meshes/left_shoulder_visual.stl"/>
</geometry>
<material name="left_shoulder_material">
<color rgba="0.0901961 0.0862745 0.0784314 1.0"/>
</material>
</visual>
<collision>
<origin xyz="0 0 0" rpy="0 -0 0" />
<geometry>
<mesh filename="meshes/left_shoulder_collision.stl"/>
</geometry>
<material name="left_shoulder_material">
<color rgba="0.5 0.5 0.5 1.0"/>
</material>
</collision>
<inertial>
<origin xyz="0.00254925 -3.61369e-05 0.0287427" rpy="0 0 0"/>
<mass value="0.0845502" />
<inertia ixx="9.74309e-05" ixy="1.04145e-07"  ixz="-3.99116e-06" iyy="7.30295e-05" iyz="-7.55191e-08" izz="9.33611e-05" />
</inertial>
</link>

<link name="left_upper_arm">
<visual>
<origin xyz="0 0 0" rpy="0 -0 0" />
<geometry>
<mesh filename="meshes/left_upper_arm_visual.stl"/>
</geometry>
<material name="left_upper_arm_material">
<color rgba="0.0901961 0.0862745 0.0784314 1.0"/>
</material>
</visual>
<collision>
<origin xyz="0 0 0" rpy="0 -0 0" />
<geometry>
<mesh filename="meshes/left_upper_arm_collision.stl"/>
</geometry>
<material name="left_upper_arm_material">
<color rgba="0.5 0.5 0.5 1.0"/>
</material>
</collision>
<inertial>
<origin xyz="0.0542236 0.000478209 -0.0234837" rpy="0 0 0"/>
<mass value="0.381133" />
<inertia ixx="0.00096227" ixy="4.24092e-05"  ixz="-4.96157e-05" iyy="0.000790074" iyz="9.94275e-06" izz="0.00142027" />
</inertial>
</link>

<link name="left_lower_arm_copy_1">
<visual>
<origin xyz="0 0 0" rpy="0 -0 0" />
<geometry>
<mesh filename="meshes/left_lower_arm_copy_1_visual.stl"/>
</geometry>
<material name="left_lower_arm_copy_1_material">
<color rgba="0.0901961 0.0862745 0.0784314 1.0"/>
</material>
</visual>
<collision>
<origin xyz="0 0 0" rpy="0 -0 0" />
<geometry>
<mesh filename="meshes/left_lower_arm_copy_1_collision.stl"/>
</geometry>
<material name="left_lower_arm_copy_1_material">
<color rgba="0.5 0.5 0.5 1.0"/>
</material>
</collision>
<inertial>
<origin xyz="0.0604327 -0.000765131 0.000367157" rpy="0 0 0"/>
<mass value="0.357122" />
<inertia ixx="0.000153485" ixy="3.12276e-05"  ixz="1.55543e-05" iyy="0.00164224" iyz="-1.58018e-06" izz="0.00168978" />
</inertial>
</link>

<joint name="left_elbow_pitch" type="revolute">
<origin xyz="0.1575 -4.16334e-16 0.0033" rpy="-1.5708 -1.19349e-15 1.56366e-15" />
<parent link="left_upper_arm" />
<child link="left_lower_arm_copy_1" />
<axis xyz="0 0 1"/>
<limit effort="1" velocity="20" />
<joint_properties friction="0.0"/>
</joint>

<joint name="left_shoulder_roll" type="revolute">
<origin xyz="0.0100012 -0.0226 0.0479124" rpy="1.5708 -8.92448e-29 5.55112e-17" />
<parent link="left_shoulder" />
<child link="left_upper_arm" />
<axis xyz="0 0 1"/>
<limit effort="1" velocity="20" />
<joint_properties friction="0.0"/>
</joint>

<joint name="left_shoulder_pitch" type="revolute">
<origin xyz="3.99598e-16 0.077 0.17775" rpy="-1.5708 5.16765e-16 -1.83187e-15" />
<parent link="torso" />
<child link="left_shoulder" />
<axis xyz="0 0 1"/>
<limit effort="1" velocity="20" />
<joint_properties friction="0.0"/>
</joint>

<link name="neck">
<visual>
<origin xyz="0 0 0" rpy="0 -0 0" />
<geometry>
<mesh filename="meshes/neck_visual.stl"/>
</geometry>
<material name="neck_material">
<color rgba="0.0901961 0.0862745 0.0784314 1.0"/>
</material>
</visual>
<collision>
<origin xyz="0 0 0" rpy="0 -0 0" />
<geometry>
<mesh filename="meshes/neck_collision.stl"/>
</geometry>
<material name="neck_material">
<color rgba="0.5 0.5 0.5 1.0"/>
</material>
</collision>
<inertial>
<origin xyz="2.08516e-08 0.000118161 -0.0273091" rpy="0 0 0"/>
<mass value="0.16501" />
<inertia ixx="6.78374e-05" ixy="4.63691e-11"  ixz="2.86652e-11" iyy="5.66271e-05" iyz="2.05605e-06" izz="3.85114e-05" />
</inertial>
</link>

<link name="head">
<visual>
<origin xyz="0 0 0" rpy="0 -0 0" />
<geometry>
<mesh filename="meshes/head_visual.stl"/>
</geometry>
<material name="head_material">
<color rgba="0.0901961 0.0862745 0.0784314 1.0"/>
</material>
</visual>
<collision>
<origin xyz="0 0 0" rpy="0 -0 0" />
<geometry>
<mesh filename="meshes/head_collision.stl"/>
</geometry>
<material name="head_material">
<color rgba="0.5 0.5 0.5 1.0"/>
</material>
</collision>
<inertial>
<origin xyz="0.0665563 0.0103216 -0.000100617" rpy="0 0 0"/>
<mass value="0.473503" />
<inertia ixx="0.0019685" ixy="6.5715e-06"  ixz="-8.0299e-06" iyy="0.0014533" iyz="5.45647e-07" izz="0.00107445" />
</inertial>
</link>

<joint name="head_pitch" type="revolute">
<origin xyz="1.21431e-17 -0.000244706 -0.0425" rpy="-1.5708 1.5708 0" />
<parent link="neck" />
<child link="head" />
<axis xyz="0 0 1"/>
<limit effort="1" velocity="20" />
<joint_properties friction="0.0"/>
</joint>

<joint name="neck_yaw" type="revolute">
<origin xyz="-0.008 2.83302e-16 0.20875" rpy="-3.14159 -2.22045e-16 3.14159" />
<parent link="torso" />
<child link="neck" />
<axis xyz="0 0 1"/>
<limit effort="1" velocity="20" />
<joint_properties friction="0.0"/>
</joint>

<link name="right_shoulder">
<visual>
<origin xyz="0 0 0" rpy="0 -0 0" />
<geometry>
<mesh filename="meshes/right_shoulder_visual.stl"/>
</geometry>
<material name="right_shoulder_material">
<color rgba="0.0901961 0.0862745 0.0784314 1.0"/>
</material>
</visual>
<collision>
<origin xyz="0 0 0" rpy="0 -0 0" />
<geometry>
<mesh filename="meshes/right_shoulder_collision.stl"/>
</geometry>
<material name="right_shoulder_material">
<color rgba="0.5 0.5 0.5 1.0"/>
</material>
</collision>
<inertial>
<origin xyz="0.00254925 -3.46247e-05 -0.0287427" rpy="0 0 0"/>
<mass value="0.0845501" />
<inertia ixx="9.74312e-05" ixy="1.04639e-07"  ixz="3.99136e-06" iyy="7.30296e-05" iyz="7.5393e-08" izz="9.33615e-05" />
</inertial>
</link>

<link name="right_upper_arm">
<visual>
<origin xyz="0 0 0" rpy="0 -0 0" />
<geometry>
<mesh filename="meshes/right_upper_arm_visual.stl"/>
</geometry>
<material name="right_upper_arm_material">
<color rgba="0.0901961 0.0862745 0.0784314 1.0"/>
</material>
</visual>
<collision>
<origin xyz="0 0 0" rpy="0 -0 0" />
<geometry>
<mesh filename="meshes/right_upper_arm_collision.stl"/>
</geometry>
<material name="right_upper_arm_material">
<color rgba="0.5 0.5 0.5 1.0"/>
</material>
</collision>
<inertial>
<origin xyz="0.0541903 -0.000312146 -0.0238983" rpy="0 0 0"/>
<mass value="0.381122" />
<inertia ixx="0.000962629" ixy="-4.43921e-05"  ixz="-4.5297e-05" iyy="0.000789657" iyz="-1.00569e-05" izz="0.00141939" />
</inertial>
</link>

<link name="left_lower_arm">
<visual>
<origin xyz="0 0 0" rpy="0 -0 0" />
<geometry>
<mesh filename="meshes/left_lower_arm_visual.stl"/>
</geometry>
<material name="left_lower_arm_material">
<color rgba="0.0901961 0.0862745 0.0784314 1.0"/>
</material>
</visual>
<collision>
<origin xyz="0 0 0" rpy="0 -0 0" />
<geometry>
<mesh filename="meshes/left_lower_arm_collision.stl"/>
</geometry>
<material name="left_lower_arm_material">
<color rgba="0.5 0.5 0.5 1.0"/>
</material>
</collision>
<inertial>
<origin xyz="0.0604361 -0.000764293 0.00013369" rpy="0 0 0"/>
<mass value="0.357162" />
<inertia ixx="0.000153514" ixy="3.13907e-05"  ixz="-1.97182e-05" iyy="0.00164255" iyz="1.59132e-06" izz="0.00169012" />
</inertial>
</link>

<joint name="right_elbow_pitch" type="revolute">
<origin xyz="0.157491 0.000314045 0.00263175" rpy="-1.5708 1.18239e-14 2.57201e-14" />
<parent link="right_upper_arm" />
<child link="left_lower_arm" />
<axis xyz="0 0 1"/>
<limit effort="1" velocity="20" />
<joint_properties friction="0.0"/>
</joint>

<joint name="right_shoulder_roll" type="revolute">
<origin xyz="0.0100012 -0.0226 -0.0479124" rpy="1.5708 6.16764e-29 1.11022e-16" />
<parent link="right_shoulder" />
<child link="right_upper_arm" />
<axis xyz="0 0 1"/>
<limit effort="1" velocity="20" />
<joint_properties friction="0.0"/>
</joint>

<joint name="right_shoulder_pitch" type="revolute">
<origin xyz="1.17933e-16 -0.077 0.17775" rpy="-1.5708 4.4981e-16 -1.83187e-15" />
<parent link="torso" />
<child link="right_shoulder" />
<axis xyz="0 0 1"/>
<limit effort="1" velocity="20" />
<joint_properties friction="0.0"/>
</joint>


</robot>
