<?xml version="1.0" ?>
<robot name="simple_robot">
  <joint name="right_hip_pitch" type="revolute">
    <parent link="torso"/>
    <child link="right_upper_leg"/>
    <origin rpy="0 0 0" xyz="0 -0.05 0"/>
    <axis xyz="0 1 0"/>
  </joint>
  <joint name="left_hip_pitch" type="revolute">
    <parent link="torso"/>
    <child link="left_upper_leg"/>
    <origin rpy="0 0 0" xyz="0 0.05 0"/>
    <axis xyz="0 1 0"/>
  </joint>
  <joint name="right_knee_pitch" type="revolute">
    <parent link="right_upper_leg"/>
    <child link="right_lower_leg"/>
    <origin rpy="0 0 0" xyz="0 0 -0.2"/>
    <axis xyz="0 1 0"/>
  </joint>
  <joint name="left_knee_pitch" type="revolute">
    <parent link="left_upper_leg"/>
    <child link="left_lower_leg"/>
    <origin rpy="0 0 0" xyz="0 0 -0.2"/>
    <axis xyz="0 1 0"/>
  </joint>
  <joint name="right_ankle_pitch" type="revolute">
    <parent link="right_lower_leg"/>
    <child link="right_ankle"/>
    <origin rpy="0 0 0" xyz="0 0 -0.2"/>
    <axis xyz="0 1 0"/>
  </joint>
  <joint name="left_ankle_pitch" type="revolute">
    <parent link="left_lower_leg"/>
    <child link="left_ankle"/>
    <origin rpy="0 0 0" xyz="0 0 -0.2"/>
    <axis xyz="0 1 0"/>
  </joint>
  <joint name="right_ankle_roll" type="revolute">
    <parent link="right_ankle"/>
    <child link="right_foot"/>
    <origin rpy="0 0 0" xyz="0 0 0"/>
    <axis xyz="1 0 0"/>
  </joint>
  <joint name="left_ankle_roll" type="revolute">
    <parent link="left_ankle"/>
    <child link="left_foot"/>
    <origin rpy="0 0 0" xyz="0 0 0"/>
    <axis xyz="1 0 0"/>
  </joint>
  <link name="torso">
    <inertial>
      <mass value="0.1"/>
      <origin rpy="0  0  0" xyz="0 0 0.2"/>
      <inertia ixx="0" ixy="0" ixz="0" iyy="0" iyz="0" izz="0"/>
    </inertial>
    <collision name="torso_collision">
      <origin rpy="0 0 0" xyz="0  0  0"/>
      <geometry>
        <mesh filename="torso.stl" scale="1 1 1"/>
      </geometry>
    </collision>
    <visual name="torso_visual">
      <origin rpy="0 0 0" xyz="0  0  0"/>
      <geometry>
        <mesh filename="torso.stl" scale="1 1 1"/>
      </geometry>
    </visual>
  </link>
  <link name="right_upper_leg">
    <inertial>
      <mass value="0.1"/>
      <origin rpy="0  0  0" xyz="0 0 -0.1"/>
      <inertia ixx="0" ixy="0" ixz="0" iyy="0" iyz="0" izz="0"/>
    </inertial>
    <collision name="right_upper_leg_collision">
      <origin rpy="0  0  0" xyz="0  0  0"/>
      <geometry>
        <mesh filename="upper_leg.stl" scale="1 1 1"/>
      </geometry>
    </collision>
    <visual name="right_upper_leg_visual">
      <origin rpy="0  0  0" xyz="0  0  0"/>
      <geometry>
        <mesh filename="upper_leg.stl" scale="1 1 1"/>
      </geometry>
    </visual>
  </link>
  <link name="left_upper_leg">
    <inertial>
      <mass value="0.1"/>
      <origin rpy="0  0  0" xyz="0 0 -0.1"/>
      <inertia ixx="0" ixy="0" ixz="0" iyy="0" iyz="0" izz="0"/>
    </inertial>
    <collision name="left_upper_leg_collision">
      <origin rpy="0  0  0" xyz="0  0  0"/>
      <geometry>
        <mesh filename="upper_leg.stl" scale="1 1 1"/>
      </geometry>
    </collision>
    <visual name="left_upper_leg_visual">
      <origin rpy="0  0  0" xyz="0  0  0"/>
      <geometry>
        <mesh filename="upper_leg.stl" scale="1 1 1"/>
      </geometry>
    </visual>
  </link>
  <link name="right_lower_leg">
    <inertial>
      <mass value="0.1"/>
      <origin rpy="0  0  0" xyz="0 0 -0.1"/>
      <inertia ixx="0" ixy="0" ixz="0" iyy="0" iyz="0" izz="0"/>
    </inertial>
    <collision name="right_lower_leg_collision">
      <origin rpy="0  0  0" xyz="0  0  0"/>
      <geometry>
        <mesh filename="lower_leg.stl" scale="1 1 1"/>
      </geometry>
    </collision>
    <visual name="right_lower_leg_visual">
      <origin rpy="0  0  0" xyz="0  0  0"/>
      <geometry>
        <mesh filename="lower_leg.stl" scale="1 1 1"/>
      </geometry>
    </visual>
  </link>
  <link name="left_lower_leg">
    <inertial>
      <mass value="0.1"/>
      <origin rpy="0  0  0" xyz="-0.1"/>
      <inertia ixx="0" ixy="0" ixz="0" iyy="0" iyz="0" izz="0"/>
    </inertial>
    <collision name="left_lower_leg_collision">
      <origin rpy="0  0  0" xyz="0  0  0"/>
      <geometry>
        <mesh filename="lower_leg.stl" scale="1 1 1"/>
      </geometry>
    </collision>
    <visual name="left_lower_leg_visual">
      <origin rpy="0  0  0" xyz="0  0  0"/>
      <geometry>
        <mesh filename="lower_leg.stl" scale="1 1 1"/>
      </geometry>
    </visual>
  </link>
  <link name="right_ankle">
    <inertial>
      <mass value="0"/>
      <origin rpy="0  0  0" xyz="0 0 0"/>
      <inertia ixx="0" ixy="0" ixz="0" iyy="0" iyz="0" izz="0"/>
    </inertial>
  </link>
  <link name="left_ankle">
    <inertial>
      <mass value="0"/>
      <origin rpy="0  0  0" xyz="0 0 0"/>
      <inertia ixx="0" ixy="0" ixz="0" iyy="0" iyz="0" izz="0"/>
    </inertial>
  </link>
  <link name="right_foot">
    <inertial>
      <mass value="0.1"/>
      <origin rpy="0  0  0" xyz="0 0 0"/>
      <inertia ixx="0" ixy="0" ixz="0" iyy="0" iyz="0" izz="0"/>
    </inertial>
    <collision name="right_foot_collision">
      <origin rpy="0  0  0" xyz="0  0  0"/>
      <geometry>
        <mesh filename="left_foot.stl" scale="1 1 1"/>
      </geometry>
    </collision>
    <visual name="right_foot_visual">
      <origin rpy="0  0  0" xyz="0  0  0"/>
      <geometry>
        <mesh filename="left_foot.stl" scale="1 1 1"/>
      </geometry>
    </visual>
  </link>
  <link name="left_foot">
    <inertial>
      <mass value="0.1"/>
      <origin rpy="0  0  0" xyz="0 0 0"/>
      <inertia ixx="0" ixy="0" ixz="0" iyy="0" iyz="0" izz="0"/>
    </inertial>
    <collision name="right_foot_collision">
      <origin rpy="0  0  0" xyz="0  0  0"/>
      <geometry>
        <mesh filename="left_foot.stl" scale="1 1 1"/>
      </geometry>
    </collision>
    <visual name="right_foot_visual">
      <origin rpy="0  0  0" xyz="0  0  0"/>
      <geometry>
        <mesh filename="left_foot.stl" scale="1 1 1"/>
      </geometry>
    </visual>
  </link>
</robot>
